Workbook

Sheet Lees mij
A1: KetelCheck — financieel plan v2 (startdienst: vervanging gasketel, Brussel + Vlaamse Rand)
A2: Versie 23-10-2026 · alle bedragen excl. btw · Marhaba Data & AI Agent BV
A4: Wat is nieuw t.o.v. v1
A5: 1. CPL is expliciet per FORMULIERINZENDING (inclusief ongeldige en dubbele). Kost per geldige en per betaalde aanvraag worden afgeleid.
A6: 2. Trechter: inzending → geldig → aanvaard (1e of 2e partner, nooit beide) → gecrediteerd → gefactureerd → betaald (wanbetaling) → ontvangen 1 maand later.
A7: 3. Elke aanvraag wordt maximaal ÉÉN keer verkocht. Een tweede partner krijgt ze enkel nadat de eerste weigerde of niet reageerde. Geen meervoudige verkoop in dit model.
A8: 4. Alle eigen tijd apart: controle per inzending, afhandeling per aanvaarde, credits, partnerwerving (eenmalig per nieuwe partner + vervanging), facturatie per partner, ads-beheer, administratie, platformonderhoud.
A9: 5. Twee resultaten: CASH (geldstromen, eigen tijd telt niet) en RESULTAAT NA EIGEN TIJD (uren × €75). Plus effectief uurloon.
A10: 6. Tab 'Partnerwaarde': wat een aanvraag een installateur waard is (brutomarge × kans op opdracht) → onderbouwing van €60 / €80 / €90.
A11: 7. Tab 'Beslisdrempels': doorgaan / bijsturen / stoppen.
A13: BELANGRIJK
A14: Blauwe cijfers zijn AANNAMES tenzij in kolom 'Bron' anders staat. €80–90 per aanvraag en €12–15 CPL zijn TESTHYPOTHESES, geen gemeten waarden.
... A22: Facturen aan Belgische btw-plichtige partners: gestructureerde e-factuur via Peppol, verplicht sinds 1/1/2026.

Sheet Inputs
B1: Inputs en aannames
B3: Actief scenario (1, 2 of 3) | C3: 2 | D3: =INDEX(C5:E5,1,C3) -> Testhypothese
B5: Scenario-aanname | C5: Voorzichtig | D5: Testhypothese | E5: Gunstig | F5: Actief | G5: Echt gemeten | H5: Bron / hoe vaststellen
B6: Geldige inzendingen (% van alle inzendingen) | C6: 0.55 | D6: 0.65 | E6: 0.75 | F6: =IF(ISNUMBER(G6),G6,INDEX(C6:E6,1,$C$3)) -> 0.65 | H6: AANNAME. Meten: aandeel dat je op 'gecontroleerd' zet. Ongeldig = dubbel, buiten regio/dienst, vals, onbereikbaar.
B7: Uiteindelijk aanvaard door 1e of 2e partner (% van geldige) | C7: 0.65 | D7: 0.8 | E7: 0.9 | F7: =IF(ISNUMBER(G7),G7,INDEX(C7:E7,1,$C$3)) -> 0.8 | H7: AANNAME. Meten: Toewijzingen 'aanvaard' / geldige. Zakt bij volle agenda's (winter).
B8: Vergoeding per aanvaarde aanvraag (€ excl. btw) | C8: 60 | D8: 80 | E8: 90 | F8: =IF(ISNUMBER(G8),G8,INDEX(C8:E8,1,$C$3)) -> 80 | H8: TESTHYPOTHESE. Onderbouwing in tab Partnerwaarde. Vaststellen: getekende pilots.
B9: Goedgekeurde credits (% van aanvaarde) | C9: 0.12 | D9: 0.08 | E9: 0.05 | F9: =IF(ISNUMBER(G9),G9,INDEX(C9:E9,1,$C$3)) -> 0.08 | H9: AANNAME. Meten: gecrediteerd / aanvaard.
B10: Wanbetaling (% van gefactureerd) | C10: 0.05 | D10: 0.03 | E10: 0.01 | F10: =IF(ISNUMBER(G10),G10,INDEX(C10:E10,1,$C$3)) -> 0.03 | H10: AANNAME. Meten: oninbaar / gefactureerd. Pilot met kleine bedragen = beperkt risico per partner.
B11: CPL: advertentiekost per formulierinzending (€) | C11: 22 | D11: 15 | E11: 12 | F11: =IF(ISNUMBER(G11),G11,INDEX(C11:E11,1,$C$3)) -> 15 | H11: TESTHYPOTHESE. = ads-uitgaven / alle inzendingen (incl. ongeldig). Vaststellen: advertentietest.
B12: Controle per inzending (minuten) | C12: 10 | D12: 7 | E12: 5 | F12: =IF(ISNUMBER(G12),G12,INDEX(C12:E12,1,$C$3)) -> 7 | H12: AANNAME. Lezen, eventueel kort bellen, status zetten, doorsturen.
B13: Afhandeling per aanvaarde aanvraag (minuten) | C13: 10 | D13: 6 | E13: 4 | F13: =IF(ISNUMBER(G13),G13,INDEX(C13:E13,1,$C$3)) -> 6 | H13: AANNAME. Vragen van aanvrager/partner, opvolging.
B14: Behandeling per creditvraag (minuten) | C14: 20 | D14: 15 | E14: 10 | F14: =IF(ISNUMBER(G14),G14,INDEX(C14:E14,1,$C$3)) -> 15 | H14: AANNAME. Bewijs opvragen, beslissen, mailen.
B15: Partnerwerving: uren per NIEUW getekende partner | C15: 6 | D15: 4 | E15: 3 | F15: =IF(ISNUMBER(G15),G15,INDEX(C15:E15,1,$C$3)) -> 4 | H15: AANNAME. ±15–25 belpogingen + gesprek + onboarding per tekenende partner.
B16: Partnerverloop per maand (% partners te vervangen) | C16: 0.1 | D16: 0.07 | E16: 0.05 | F16: =IF(ISNUMBER(G16),G16,INDEX(C16:E16,1,$C$3)) -> 0.07 | H16: AANNAME.
B17: Aanvaarde aanvragen per partner per maand (capaciteit) | C17: 4 | D17: 6 | E17: 8 | F17: =IF(ISNUMBER(G17),G17,INDEX(C17:E17,1,$C$3)) -> 6 | H17: AANNAME. Vraag in elk partnergesprek; staat als max_per_week in de Sheet.
... B22: Software/tools (€/maand) | C22: 25 | D22: 15 | E22: 10 | F22: =IF(ISNUMBER(G22),G22,INDEX(C22:E22,1,$C$3)) -> 15 | H22: AANNAME. Domein ±€1/m; Google gratis; Peppol-tool: €0 marginaal als Marhaba BV er al één heeft, anders €10–25/m. Te bevestigen.
B24: Algemene inputs | C24: Waarde | H24: Bron / uitleg
B25: Uurtarief eigen tijd (€/u) | C25: 75 | H25: Gegeven door Mohamed.
B26: Betaalkosten (% van ontvangen) | C26: 0.01 | H26: AANNAME.
B27: Eenmalige cash-opstart (€) | C27: 70 | H27: Domein, mailbox; zie Testbudget.
B28: Eenmalige tijd: deploy, teksten, tests in echte omgeving (uren) | C28: 6 | H28: AANNAME (onbewezen): 2–4 u deploy + 2 u echte end-to-end test.
B29: Werkdagen per maand | C29: 21 | H29: Voor 'minuten per werkdag'.
B30: Doelresultaat per uur eigen tijd (€) | C30: 75 | H30: Keuze: wat je tijd moet opbrengen om door te gaan.
B31: Startbudget-plafond (€) | C31: 10000 | H31: Gegeven door Mohamed.
B32: Validatietest extern budget (€) | C32: 1000 | H32: Gegeven door Mohamed.

Sheet Unit economics
B1: Maandmodel — actief scenario
B2: ="Scenario: "&Inputs!D3&" · inzendingen per maand in rij 5 aanpasbaar" -> Scenario: Testhypothese · inzendingen per maand in rij 5 aanpasbaar
B3: Inzendingen per maand → | C3: 20 | D3: 50 | E3: 100
B4: Regel | C4: Volume 1 | D4: Volume 2 | E4: Volume 3
B5: Formulierinzendingen | C5: =C3 -> 20 | D5: =D3 -> 50 | E5: =E3 -> 100
B6: Geldige inzendingen | C6: =C5*Inputs!$F$6 -> 13 | D6: =D5*Inputs!$F$6 -> 32.5 | E6: =E5*Inputs!$F$6 -> 65
B7: Aanvaarde aanvragen (max. 1 verkoop per aanvraag) | C7: =C6*Inputs!$F$7 -> 10.4 | D7: =D6*Inputs!$F$7 -> 26 | E7: =E6*Inputs!$F$7 -> 52
B8: Gecrediteerd (aantal) | C8: =C7*Inputs!$F$9 -> 0.832 | D8: =D7*Inputs!$F$9 -> 2.08 | E8: =E7*Inputs!$F$9 -> 4.16
B9: Gefactureerd (aantal) | C9: =C7-C8 -> 9.568 | D9: =D7-D8 -> 23.92 | E9: =E7-E8 -> 47.84
B10: Omzet (gefactureerd) | C10: =C9*Inputs!$F$8 -> 765.44 | D10: =D9*Inputs!$F$8 -> 1913.6 | E10: =E9*Inputs!$F$8 -> 3827.2
B11: Wanbetaling | C11: =-C10*Inputs!$F$10 -> -22.9632 | D11: =-D10*Inputs!$F$10 -> -57.408 | E11: =-E10*Inputs!$F$10 -> -114.816
B12: Betaalkosten | C12: =-(C10+C11)*Inputs!$C$26 -> -7.424768 | D12: =-(D10+D11)*Inputs!$C$26 -> -18.56192 | E12: =-(E10+E11)*Inputs!$C$26 -> -37.12384
B13: Advertenties (CPL × inzendingen) | C13: =-C5*Inputs!$F$11 -> -300 | D13: =-D5*Inputs!$F$11 -> -750 | E13: =-E5*Inputs!$F$11 -> -1500
B14: Software/tools | C14: =-Inputs!$F$22 -> -15 | D14: =-Inputs!$F$22 -> -15 | E14: =-Inputs!$F$22 -> -15
B15: CASHRESULTAAT (zonder eigen tijd) | C15: =SUM(C10:C14) -> 420.05203 | D15: =SUM(D10:D14) -> 1072.6301 | E15: =SUM(E10:E14) -> 2160.2602
B16: Benodigde actieve partners | C16: =IF(Inputs!$F$17>0,ROUNDUP(C7/Inputs!$F$17,0),0) -> 2 | D16: =IF(Inputs!$F$17>0,ROUNDUP(D7/Inputs!$F$17,0),0) -> 5 | E16: =IF(Inputs!$F$17>0,ROUNDUP(E7/Inputs!$F$17,0),0) -> 9
B17: Uren: controle inzendingen | C17: =C5*Inputs!$F$12/60 -> 2.3333333 | D17: =D5*Inputs!$F$12/60 -> 5.8333333 | E17: =E5*Inputs!$F$12/60 -> 11.666667
B18: Uren: afhandeling aanvaarde | C18: =C7*Inputs!$F$13/60 -> 1.04 | D18: =D7*Inputs!$F$13/60 -> 2.6 | E18: =E7*Inputs!$F$13/60 -> 5.2
B19: Uren: creditvragen | C19: =C8*Inputs!$F$14/60 -> 0.208 | D19: =D8*Inputs!$F$14/60 -> 0.52 | E19: =E8*Inputs!$F$14/60 -> 1.04
B20: Uren: facturatie per partner | C20: =C16*Inputs!$F$18/60 -> 0.66666667 | D20: =D16*Inputs!$F$18/60 -> 1.6666667 | E20: =E16*Inputs!$F$18/60 -> 3
B21: Uren: partnerwerving (verloop vervangen) | C21: =C16*Inputs!$F$16*Inputs!$F$15 -> 0.56 | D21: =D16*Inputs!$F$16*Inputs!$F$15 -> 1.4 | E21: =E16*Inputs!$F$16*Inputs!$F$15 -> 2.52
B22: Uren: ads, administratie, platform | C22: =Inputs!$F$19+Inputs!$F$20+Inputs!$F$21 -> 8 | D22: =Inputs!$F$19+Inputs!$F$20+Inputs!$F$21 -> 8 | E22: =Inputs!$F$19+Inputs!$F$20+Inputs!$F$21 -> 8
B23: Totaal uren eigen tijd per maand | C23: =SUM(C17:C22) -> 12.808 | D23: =SUM(D17:D22) -> 20.02 | E23: =SUM(E17:E22) -> 31.426667
B24: Minuten per werkdag | C24: =C23*60/Inputs!$C$29 -> 36.594286 | D24: =D23*60/Inputs!$C$29 -> 57.2 | E24: =E23*60/Inputs!$C$29 -> 89.790476
B25: Eigen tijd à uurtarief | C25: =-C23*Inputs!$C$25 -> -960.6 | D25: =-D23*Inputs!$C$25 -> -1501.5 | E25: =-E23*Inputs!$C$25 -> -2357
B26: RESULTAAT NA EIGEN TIJD | C26: =C15+C25 -> -540.54797 | D26: =D15+D25 -> -428.86992 | E26: =E15+E25 -> -196.73984
B27: Effectief uurloon (cashresultaat / uren) | C27: =IF(C23>0,C15/C23,0) -> 32.796067 | D27: =IF(D23>0,D15/D23,0) -> 53.577926 | E27: =IF(E23>0,E15/E23,0) -> 68.739717
B28: Advertentiekost per geldige aanvraag | C28: =IF(C6>0,-C13/C6,0) -> 23.076923 | D28: =IF(D6>0,-D13/D6,0) -> 23.076923 | E28: =IF(E6>0,-E13/E6,0) -> 23.076923
B29: Advertentiekost per gefactureerde aanvraag | C29: =IF(C9>0,-C13/C9,0) -> 31.354515 | D29: =IF(D9>0,-D13/D9,0) -> 31.354515 | E29: =IF(E9>0,-E13/E9,0) -> 31.354515
B31: Drempels (actief scenario)
B32: Cash-bijdrage per inzending vóór ads | C32: =Inputs!$F$6*Inputs!$F$7*(1-Inputs!$F$9)*Inputs!$F$8*(1-Inputs!$F$10)*(1-Inputs!$C$26) -> 36.752602
B33: Variabele tijdkost per inzending (controle, afhandeling, credits, werving, facturatie) | C33: =(Inputs!$F$12/60+Inputs!$F$6*Inputs!$F$7*(Inputs!$F$13/60+Inputs!$F$9*Inputs!$F$14/60+IF(Inputs!$F$17>0,1/Inputs!$F$17,0)*(Inputs!$F$18/60+Inputs!$F$16*Inputs!$F$15)))*Inputs!$C$25 -> 17.416667
B34: Vaste kosten per maand (vaste uren × tarief + software) | C34: =(Inputs!$F$19+Inputs!$F$20+Inputs!$F$21)*Inputs!$C$25+Inputs!$F$22 -> 615
B35: Max. CPL voor CASH break-even (vaste uren niet betaald) | C35: =C32-Inputs!$F$22/C3 -> 36.002602 | D35: =C32-Inputs!$F$22/D3 -> 36.452602 | E35: =C32-Inputs!$F$22/E3 -> 36.602602
B36: Max. CPL voor break-even NA eigen tijd à uurtarief | C36: =$C$32-$C$33-$C$34/C3 -> -11.414065 | D36: =$C$32-$C$33-$C$34/D3 -> 7.0359349 | E36: =$C$32-$C$33-$C$34/E3 -> 13.185935 | F36: Elke inzending kost CPL, ook als ze ongeldig is.
B37: Inzendingen/maand nodig voor €0 na eigen tijd (bij actieve CPL) | C37: =IF(C32-C33-Inputs!$F$11>0,C34/(C32-C33-Inputs!$F$11),"onhaalbaar") -> 141.83792
B38: Inzendingen/maand nodig voor €1.000 na eigen tijd | C38: =IF(C32-C33-Inputs!$F$11>0,(1000+C34)/(C32-C33-Inputs!$F$11),"onhaalbaar") -> 372.46869
B39: Inzendingen/maand nodig voor €3.000 na eigen tijd | C39: =IF(C32-C33-Inputs!$F$11>0,(3000+C34)/(C32-C33-Inputs!$F$11),"onhaalbaar") -> 833.73022
B40: Partners nodig bij €3.000-volume | C40: =IF(ISNUMBER(C39),ROUNDUP(C39*Inputs!$F$6*Inputs!$F$7/Inputs!$F$17,0),"-") -> 73

Sheet Scenario's
B1: Alle scenario's naast elkaar (kolommen C/D/E van Inputs, niet 'Echt gemeten')
C3: 20 | D3: 50 | E3: 100 | F3: 20 | G3: 50 | H3: 100 | I3: 20 | J3: 50 | K3: 100
B4: Regel | C4: Voorz. 20 | D4: Voorz. 50 | E4: Voorz. 100 | F4: Test 20 | G4: Test 50 | H4: Test 100 | I4: Gunstig 20 | J4: Gunstig 50 | K4: Gunstig 100
B5: Formulierinzendingen | C5: =C3 -> 20 | D5: =D3 -> 50 | E5: =E3 -> 100 | F5: =F3 -> 20 | G5: =G3 -> 50 | H5: =H3 -> 100 | I5: =I3 -> 20 | J5: =J3 -> 50 | K5: =K3 -> 100
B6: Geldige inzendingen | C6: =C5*Inputs!$C$6 -> 11 | D6: =D5*Inputs!$C$6 -> 27.5 | E6: =E5*Inputs!$C$6 -> 55 | F6: =F5*Inputs!$D$6 -> 13 | G6: =G5*Inputs!$D$6 -> 32.5 | H6: =H5*Inputs!$D$6 -> 65 | I6: =I5*Inputs!$E$6 -> 15 | J6: =J5*Inputs!$E$6 -> 37.5 | K6: =K5*Inputs!$E$6 -> 75
B7: Aanvaarde aanvragen (max. 1 verkoop per aanvraag) | C7: =C6*Inputs!$C$7 -> 7.15 | D7: =D6*Inputs!$C$7 -> 17.875 | E7: =E6*Inputs!$C$7 -> 35.75 | F7: =F6*Inputs!$D$7 -> 10.4 | G7: =G6*Inputs!$D$7 -> 26 | H7: =H6*Inputs!$D$7 -> 52 | I7: =I6*Inputs!$E$7 -> 13.5 | J7: =J6*Inputs!$E$7 -> 33.75 | K7: =K6*Inputs!$E$7 -> 67.5
B8: Gecrediteerd (aantal) | C8: =C7*Inputs!$C$9 -> 0.858 | D8: =D7*Inputs!$C$9 -> 2.145 | E8: =E7*Inputs!$C$9 -> 4.29 | F8: =F7*Inputs!$D$9 -> 0.832 | G8: =G7*Inputs!$D$9 -> 2.08 | H8: =H7*Inputs!$D$9 -> 4.16 | I8: =I7*Inputs!$E$9 -> 0.675 | J8: =J7*Inputs!$E$9 -> 1.6875 | K8: =K7*Inputs!$E$9 -> 3.375
B9: Gefactureerd (aantal) | C9: =C7-C8 -> 6.292 | D9: =D7-D8 -> 15.73 | E9: =E7-E8 -> 31.46 | F9: =F7-F8 -> 9.568 | G9: =G7-G8 -> 23.92 | H9: =H7-H8 -> 47.84 | I9: =I7-I8 -> 12.825 | J9: =J7-J8 -> 32.0625 | K9: =K7-K8 -> 64.125
B10: Omzet (gefactureerd) | C10: =C9*Inputs!$C$8 -> 377.52 | D10: =D9*Inputs!$C$8 -> 943.8 | E10: =E9*Inputs!$C$8 -> 1887.6 | F10: =F9*Inputs!$D$8 -> 765.44 | G10: =G9*Inputs!$D$8 -> 1913.6 | H10: =H9*Inputs!$D$8 -> 3827.2 | I10: =I9*Inputs!$E$8 -> 1154.25 | J10: =J9*Inputs!$E$8 -> 2885.625 | K10: =K9*Inputs!$E$8 -> 5771.25
B11: Wanbetaling | C11: =-C10*Inputs!$C$10 -> -18.876 | D11: =-D10*Inputs!$C$10 -> -47.19 | E11: =-E10*Inputs!$C$10 -> -94.38 | F11: =-F10*Inputs!$D$10 -> -22.9632 | G11: =-G10*Inputs!$D$10 -> -57.408 | H11: =-H10*Inputs!$D$10 -> -114.816 | I11: =-I10*Inputs!$E$10 -> -11.5425 | J11: =-J10*Inputs!$E$10 -> -28.85625 | K11: =-K10*Inputs!$E$10 -> -57.7125
B12: Betaalkosten | C12: =-(C10+C11)*Inputs!$C$26 -> -3.58644 | D12: =-(D10+D11)*Inputs!$C$26 -> -8.9661 | E12: =-(E10+E11)*Inputs!$C$26 -> -17.9322 | F12: =-(F10+F11)*Inputs!$C$26 -> -7.424768 | G12: =-(G10+G11)*Inputs!$C$26 -> -18.56192 | H12: =-(H10+H11)*Inputs!$C$26 -> -37.12384 | I12: =-(I10+I11)*Inputs!$C$26 -> -11.427075 | J12: =-(J10+J11)*Inputs!$C$26 -> -28.567688 | K12: =-(K10+K11)*Inputs!$C$26 -> -57.135375
B13: Advertenties (CPL × inzendingen) | C13: =-C5*Inputs!$C$11 -> -440 | D13: =-D5*Inputs!$C$11 -> -1100 | E13: =-E5*Inputs!$C$11 -> -2200 | F13: =-F5*Inputs!$D$11 -> -300 | G13: =-G5*Inputs!$D$11 -> -750 | H13: =-H5*Inputs!$D$11 -> -1500 | I13: =-I5*Inputs!$E$11 -> -240 | J13: =-J5*Inputs!$E$11 -> -600 | K13: =-K5*Inputs!$E$11 -> -1200
B14: Software/tools | C14: =-Inputs!$C$22 -> -25 | D14: =-Inputs!$C$22 -> -25 | E14: =-Inputs!$C$22 -> -25 | F14: =-Inputs!$D$22 -> -15 | G14: =-Inputs!$D$22 -> -15 | H14: =-Inputs!$D$22 -> -15 | I14: =-Inputs!$E$22 -> -10 | J14: =-Inputs!$E$22 -> -10 | K14: =-Inputs!$E$22 -> -10
B15: CASHRESULTAAT (zonder eigen tijd) | C15: =SUM(C10:C14) -> -109.94244 | D15: =SUM(D10:D14) -> -237.3561 | E15: =SUM(E10:E14) -> -449.7122 | F15: =SUM(F10:F14) -> 420.05203 | G15: =SUM(G10:G14) -> 1072.6301 | H15: =SUM(H10:H14) -> 2160.2602 | I15: =SUM(I10:I14) -> 881.28043 | J15: =SUM(J10:J14) -> 2218.2011 | K15: =SUM(K10:K14) -> 4446.4021
B16: Benodigde actieve partners | C16: =IF(Inputs!$C$17>0,ROUNDUP(C7/Inputs!$C$17,0),0) -> 2 | D16: =IF(Inputs!$C$17>0,ROUNDUP(D7/Inputs!$C$17,0),0) -> 5 | E16: =IF(Inputs!$C$17>0,ROUNDUP(E7/Inputs!$C$17,0),0) -> 9 | F16: =IF(Inputs!$D$17>0,ROUNDUP(F7/Inputs!$D$17,0),0) -> 2 | G16: =IF(Inputs!$D$17>0,ROUNDUP(G7/Inputs!$D$17,0),0) -> 5 | H16: =IF(Inputs!$D$17>0,ROUNDUP(H7/Inputs!$D$17,0),0) -> 9 | I16: =IF(Inputs!$E$17>0,ROUNDUP(I7/Inputs!$E$17,0),0) -> 2 | J16: =IF(Inputs!$E$17>0,ROUNDUP(J7/Inputs!$E$17,0),0) -> 5 | K16: =IF(Inputs!$E$17>0,ROUNDUP(K7/Inputs!$E$17,0),0) -> 9
B17: Uren: controle inzendingen | C17: =C5*Inputs!$C$12/60 -> 3.3333333 | D17: =D5*Inputs!$C$12/60 -> 8.3333333 | E17: =E5*Inputs!$C$12/60 -> 16.666667 | F17: =F5*Inputs!$D$12/60 -> 2.3333333 | G17: =G5*Inputs!$D$12/60 -> 5.8333333 | H17: =H5*Inputs!$D$12/60 -> 11.666667 | I17: =I5*Inputs!$E$12/60 -> 1.6666667 | J17: =J5*Inputs!$E$12/60 -> 4.1666667 | K17: =K5*Inputs!$E$12/60 -> 8.3333333
B18: Uren: afhandeling aanvaarde | C18: =C7*Inputs!$C$13/60 -> 1.1916667 | D18: =D7*Inputs!$C$13/60 -> 2.9791667 | E18: =E7*Inputs!$C$13/60 -> 5.9583333 | F18: =F7*Inputs!$D$13/60 -> 1.04 | G18: =G7*Inputs!$D$13/60 -> 2.6 | H18: =H7*Inputs!$D$13/60 -> 5.2 | I18: =I7*Inputs!$E$13/60 -> 0.9 | J18: =J7*Inputs!$E$13/60 -> 2.25 | K18: =K7*Inputs!$E$13/60 -> 4.5
B19: Uren: creditvragen | C19: =C8*Inputs!$C$14/60 -> 0.286 | D19: =D8*Inputs!$C$14/60 -> 0.715 | E19: =E8*Inputs!$C$14/60 -> 1.43 | F19: =F8*Inputs!$D$14/60 -> 0.208 | G19: =G8*Inputs!$D$14/60 -> 0.52 | H19: =H8*Inputs!$D$14/60 -> 1.04 | I19: =I8*Inputs!$E$14/60 -> 0.1125 | J19: =J8*Inputs!$E$14/60 -> 0.28125 | K19: =K8*Inputs!$E$14/60 -> 0.5625
B20: Uren: facturatie per partner | C20: =C16*Inputs!$C$18/60 -> 1 | D20: =D16*Inputs!$C$18/60 -> 2.5 | E20: =E16*Inputs!$C$18/60 -> 4.5 | F20: =F16*Inputs!$D$18/60 -> 0.66666667 | G20: =G16*Inputs!$D$18/60 -> 1.6666667 | H20: =H16*Inputs!$D$18/60 -> 3 | I20: =I16*Inputs!$E$18/60 -> 0.5 | J20: =J16*Inputs!$E$18/60 -> 1.25 | K20: =K16*Inputs!$E$18/60 -> 2.25
B21: Uren: partnerwerving (verloop vervangen) | C21: =C16*Inputs!$C$16*Inputs!$C$15 -> 1.2 | D21: =D16*Inputs!$C$16*Inputs!$C$15 -> 3 | E21: =E16*Inputs!$C$16*Inputs!$C$15 -> 5.4 | F21: =F16*Inputs!$D$16*Inputs!$D$15 -> 0.56 | G21: =G16*Inputs!$D$16*Inputs!$D$15 -> 1.4 | H21: =H16*Inputs!$D$16*Inputs!$D$15 -> 2.52 | I21: =I16*Inputs!$E$16*Inputs!$E$15 -> 0.3 | J21: =J16*Inputs!$E$16*Inputs!$E$15 -> 0.75 | K21: =K16*Inputs!$E$16*Inputs!$E$15 -> 1.35
B22: Uren: ads, administratie, platform | C22: =Inputs!$C$19+Inputs!$C$20+Inputs!$C$21 -> 12 | D22: =Inputs!$C$19+Inputs!$C$20+Inputs!$C$21 -> 12 | E22: =Inputs!$C$19+Inputs!$C$20+Inputs!$C$21 -> 12 | F22: =Inputs!$D$19+Inputs!$D$20+Inputs!$D$21 -> 8 | G22: =Inputs!$D$19+Inputs!$D$20+Inputs!$D$21 -> 8 | H22: =Inputs!$D$19+Inputs!$D$20+Inputs!$D$21 -> 8 | I22: =Inputs!$E$19+Inputs!$E$20+Inputs!$E$21 -> 5.5 | J22: =Inputs!$E$19+Inputs!$E$20+Inputs!$E$21 -> 5.5 | K22: =Inputs!$E$19+Inputs!$E$20+Inputs!$E$21 -> 5.5
B23: Totaal uren eigen tijd per maand | C23: =SUM(C17:C22) -> 19.011 | D23: =SUM(D17:D22) -> 29.5275 | E23: =SUM(E17:E22) -> 45.955 | F23: =SUM(F17:F22) -> 12.808 | G23: =SUM(G17:G22) -> 20.02 | H23: =SUM(H17:H22) -> 31.426667 | I23: =SUM(I17:I22) -> 8.9791667 | J23: =SUM(J17:J22) -> 14.197917 | K23: =SUM(K17:K22) -> 22.495833
B24: Minuten per werkdag | C24: =C23*60/Inputs!$C$29 -> 54.317143 | D24: =D23*60/Inputs!$C$29 -> 84.364286 | E24: =E23*60/Inputs!$C$29 -> 131.3 | F24: =F23*60/Inputs!$C$29 -> 36.594286 | G24: =G23*60/Inputs!$C$29 -> 57.2 | H24: =H23*60/Inputs!$C$29 -> 89.790476 | I24: =I23*60/Inputs!$C$29 -> 25.654762 | J24: =J23*60/Inputs!$C$29 -> 40.565476 | K24: =K23*60/Inputs!$C$29 -> 64.27381
B25: Eigen tijd à uurtarief | C25: =-C23*Inputs!$C$25 -> -1425.825 | D25: =-D23*Inputs!$C$25 -> -2214.5625 | E25: =-E23*Inputs!$C$25 -> -3446.625 | F25: =-F23*Inputs!$C$25 -> -960.6 | G25: =-G23*Inputs!$C$25 -> -1501.5 | H25: =-H23*Inputs!$C$25 -> -2357 | I25: =-I23*Inputs!$C$25 -> -673.4375 | J25: =-J23*Inputs!$C$25 -> -1064.8438 | K25: =-K23*Inputs!$C$25 -> -1687.1875
B26: RESULTAAT NA EIGEN TIJD | C26: =C15+C25 -> -1535.7674 | D26: =D15+D25 -> -2451.9186 | E26: =E15+E25 -> -3896.3372 | F26: =F15+F25 -> -540.54797 | G26: =G15+G25 -> -428.86992 | H26: =H15+H25 -> -196.73984 | I26: =I15+I25 -> 207.84293 | J26: =J15+J25 -> 1153.3573 | K26: =K15+K25 -> 2759.2146
B27: Effectief uurloon (cashresultaat / uren) | C27: =IF(C23>0,C15/C23,0) -> -5.7830961 | D27: =IF(D23>0,D15/D23,0) -> -8.038476 | E27: =IF(E23>0,E15/E23,0) -> -9.7859254 | F27: =IF(F23>0,F15/F23,0) -> 32.796067 | G27: =IF(G23>0,G15/G23,0) -> 53.577926 | H27: =IF(H23>0,H15/H23,0) -> 68.739717 | I27: =IF(I23>0,I15/I23,0) -> 98.14724 | J27: =IF(J23>0,J15/J23,0) -> 156.23426 | K27: =IF(K23>0,K15/K23,0) -> 197.65447
B28: Advertentiekost per geldige aanvraag | C28: =IF(C6>0,-C13/C6,0) -> 40 | D28: =IF(D6>0,-D13/D6,0) -> 40 | E28: =IF(E6>0,-E13/E6,0) -> 40 | F28: =IF(F6>0,-F13/F6,0) -> 23.076923 | G28: =IF(G6>0,-G13/G6,0) -> 23.076923 | H28: =IF(H6>0,-H13/H6,0) -> 23.076923 | I28: =IF(I6>0,-I13/I6,0) -> 16 | J28: =IF(J6>0,-J13/J6,0) -> 16 | K28: =IF(K6>0,-K13/K6,0) -> 16
B29: Advertentiekost per gefactureerde aanvraag | C29: =IF(C9>0,-C13/C9,0) -> 69.93007 | D29: =IF(D9>0,-D13/D9,0) -> 69.93007 | E29: =IF(E9>0,-E13/E9,0) -> 69.93007 | F29: =IF(F9>0,-F13/F9,0) -> 31.354515 | G29: =IF(G9>0,-G13/G9,0) -> 31.354515 | H29: =IF(H9>0,-H13/H9,0) -> 31.354515 | I29: =IF(I9>0,-I13/I9,0) -> 18.71345 | J29: =IF(J9>0,-J13/J9,0) -> 18.71345 | K29: =IF(K9>0,-K13/K9,0) -> 18.71345

Sheet 12 maanden
B1: 12-maandenplan — actief scenario
B2: ="Scenario: "&Inputs!D3&" · inzendingen per maand (rij 3) zijn AANNAMES: pas aan" -> Scenario: Testhypothese · inzendingen per maand (rij 3) zijn AANNAMES: pas aan
B3: Inzendingen per maand → | C3: 10 | D3: 20 | E3: 30 | F3: 35 | G3: 35 | H3: 30 | I3: 25 | J3: 20 | K3: 20 | L3: 20 | M3: 30 | N3: 40
B4: Regel | C4: nov-26 | D4: dec-26 | E4: jan-27 | F4: feb-27 | G4: mrt-27 | H4: apr-27 | I4: mei-27 | J4: jun-27 | K4: jul-27 | L4: aug-27 | M4: sep-27 | N4: okt-27 | O4: Totaal
B5: Formulierinzendingen | C5: =C3 -> 10 | D5: =D3 -> 20 | E5: =E3 -> 30 | F5: =F3 -> 35 | G5: =G3 -> 35 | H5: =H3 -> 30 | I5: =I3 -> 25 | J5: =J3 -> 20 | ... N5: =N3 -> 40 | O5: =SUM(C5:N5) -> 315
B6: Geldige inzendingen | C6: =C5*Inputs!$F$6 -> 6.5 | D6: =D5*Inputs!$F$6 -> 13 | E6: =E5*Inputs!$F$6 -> 19.5 | F6: =F5*Inputs!$F$6 -> 22.75 | G6: =G5*Inputs!$F$6 -> 22.75 | H6: =H5*Inputs!$F$6 -> 19.5 | I6: =I5*Inputs!$F$6 -> 16.25 | J6: =J5*Inputs!$F$6 -> 13 | ... N6: =N5*Inputs!$F$6 -> 26 | O6: =SUM(C6:N6) -> 204.75
B7: Aanvaarde aanvragen (max. 1 verkoop per aanvraag) | C7: =C6*Inputs!$F$7 -> 5.2 | D7: =D6*Inputs!$F$7 -> 10.4 | E7: =E6*Inputs!$F$7 -> 15.6 | F7: =F6*Inputs!$F$7 -> 18.2 | G7: =G6*Inputs!$F$7 -> 18.2 | H7: =H6*Inputs!$F$7 -> 15.6 | I7: =I6*Inputs!$F$7 -> 13 | J7: =J6*Inputs!$F$7 -> 10.4 | ... N7: =N6*Inputs!$F$7 -> 20.8 | O7: =SUM(C7:N7) -> 163.8
B8: Gecrediteerd (aantal) | C8: =C7*Inputs!$F$9 -> 0.416 | D8: =D7*Inputs!$F$9 -> 0.832 | E8: =E7*Inputs!$F$9 -> 1.248 | F8: =F7*Inputs!$F$9 -> 1.456 | G8: =G7*Inputs!$F$9 -> 1.456 | H8: =H7*Inputs!$F$9 -> 1.248 | I8: =I7*Inputs!$F$9 -> 1.04 | J8: =J7*Inputs!$F$9 -> 0.832 | ... N8: =N7*Inputs!$F$9 -> 1.664 | O8: =SUM(C8:N8) -> 13.104
B9: Gefactureerd (aantal) | C9: =C7-C8 -> 4.784 | D9: =D7-D8 -> 9.568 | E9: =E7-E8 -> 14.352 | F9: =F7-F8 -> 16.744 | G9: =G7-G8 -> 16.744 | H9: =H7-H8 -> 14.352 | I9: =I7-I8 -> 11.96 | J9: =J7-J8 -> 9.568 | ... N9: =N7-N8 -> 19.136 | O9: =SUM(C9:N9) -> 150.696
B10: Omzet (gefactureerd) | C10: =C9*Inputs!$F$8 -> 382.72 | D10: =D9*Inputs!$F$8 -> 765.44 | E10: =E9*Inputs!$F$8 -> 1148.16 | F10: =F9*Inputs!$F$8 -> 1339.52 | G10: =G9*Inputs!$F$8 -> 1339.52 | H10: =H9*Inputs!$F$8 -> 1148.16 | I10: =I9*Inputs!$F$8 -> 956.8 | J10: =J9*Inputs!$F$8 -> 765.44 | ... N10: =N9*Inputs!$F$8 -> 1530.88 | O10: =SUM(C10:N10) -> 12055.68
B11: Wanbetaling | C11: =-C10*Inputs!$F$10 -> -11.4816 | D11: =-D10*Inputs!$F$10 -> -22.9632 | E11: =-E10*Inputs!$F$10 -> -34.4448 | F11: =-F10*Inputs!$F$10 -> -40.1856 | G11: =-G10*Inputs!$F$10 -> -40.1856 | H11: =-H10*Inputs!$F$10 -> -34.4448 | I11: =-I10*Inputs!$F$10 -> -28.704 | J11: =-J10*Inputs!$F$10 -> -22.9632 | ... N11: =-N10*Inputs!$F$10 -> -45.9264 | O11: =SUM(C11:N11) -> -361.6704
B12: Betaalkosten | C12: =-(C10+C11)*Inputs!$C$26 -> -3.712384 | D12: =-(D10+D11)*Inputs!$C$26 -> -7.424768 | E12: =-(E10+E11)*Inputs!$C$26 -> -11.137152 | F12: =-(F10+F11)*Inputs!$C$26 -> -12.993344 | G12: =-(G10+G11)*Inputs!$C$26 -> -12.993344 | H12: =-(H10+H11)*Inputs!$C$26 -> -11.137152 | I12: =-(I10+I11)*Inputs!$C$26 -> -9.28096 | J12: =-(J10+J11)*Inputs!$C$26 -> -7.424768 | ... N12: =-(N10+N11)*Inputs!$C$26 -> -14.849536 | O12: =SUM(C12:N12) -> -116.9401
B13: Advertenties (CPL × inzendingen) | C13: =-C5*Inputs!$F$11 -> -150 | D13: =-D5*Inputs!$F$11 -> -300 | E13: =-E5*Inputs!$F$11 -> -450 | F13: =-F5*Inputs!$F$11 -> -525 | G13: =-G5*Inputs!$F$11 -> -525 | H13: =-H5*Inputs!$F$11 -> -450 | I13: =-I5*Inputs!$F$11 -> -375 | J13: =-J5*Inputs!$F$11 -> -300 | ... N13: =-N5*Inputs!$F$11 -> -600 | O13: =SUM(C13:N13) -> -4725
B14: Software/tools | C14: =-Inputs!$F$22 -> -15 | D14: =-Inputs!$F$22 -> -15 | E14: =-Inputs!$F$22 -> -15 | F14: =-Inputs!$F$22 -> -15 | G14: =-Inputs!$F$22 -> -15 | H14: =-Inputs!$F$22 -> -15 | I14: =-Inputs!$F$22 -> -15 | J14: =-Inputs!$F$22 -> -15 | ... N14: =-Inputs!$F$22 -> -15 | O14: =SUM(C14:N14) -> -180
B15: CASHRESULTAAT (zonder eigen tijd) | C15: =SUM(C10:C14) -> 202.52602 | D15: =SUM(D10:D14) -> 420.05203 | E15: =SUM(E10:E14) -> 637.57805 | F15: =SUM(F10:F14) -> 746.34106 | G15: =SUM(G10:G14) -> 746.34106 | H15: =SUM(H10:H14) -> 637.57805 | I15: =SUM(I10:I14) -> 528.81504 | J15: =SUM(J10:J14) -> 420.05203 | ... N15: =SUM(N10:N14) -> 855.10406 | O15: =SUM(C15:N15) -> 6672.0695
B16: Benodigde actieve partners | C16: =IF(Inputs!$F$17>0,ROUNDUP(C7/Inputs!$F$17,0),0) -> 1 | D16: =IF(Inputs!$F$17>0,ROUNDUP(D7/Inputs!$F$17,0),0) -> 2 | E16: =IF(Inputs!$F$17>0,ROUNDUP(E7/Inputs!$F$17,0),0) -> 3 | F16: =IF(Inputs!$F$17>0,ROUNDUP(F7/Inputs!$F$17,0),0) -> 4 | G16: =IF(Inputs!$F$17>0,ROUNDUP(G7/Inputs!$F$17,0),0) -> 4 | H16: =IF(Inputs!$F$17>0,ROUNDUP(H7/Inputs!$F$17,0),0) -> 3 | I16: =IF(Inputs!$F$17>0,ROUNDUP(I7/Inputs!$F$17,0),0) -> 3 | J16: =IF(Inputs!$F$17>0,ROUNDUP(J7/Inputs!$F$17,0),0) -> 2 | ... N16: =IF(Inputs!$F$17>0,ROUNDUP(N7/Inputs!$F$17,0),0) -> 4
B17: Uren: controle inzendingen | C17: =C5*Inputs!$F$12/60 -> 1.1666667 | D17: =D5*Inputs!$F$12/60 -> 2.3333333 | E17: =E5*Inputs!$F$12/60 -> 3.5 | F17: =F5*Inputs!$F$12/60 -> 4.0833333 | G17: =G5*Inputs!$F$12/60 -> 4.0833333 | H17: =H5*Inputs!$F$12/60 -> 3.5 | I17: =I5*Inputs!$F$12/60 -> 2.9166667 | J17: =J5*Inputs!$F$12/60 -> 2.3333333 | ... N17: =N5*Inputs!$F$12/60 -> 4.6666667 | O17: =SUM(C17:N17) -> 36.75
B18: Uren: afhandeling aanvaarde | C18: =C7*Inputs!$F$13/60 -> 0.52 | D18: =D7*Inputs!$F$13/60 -> 1.04 | E18: =E7*Inputs!$F$13/60 -> 1.56 | F18: =F7*Inputs!$F$13/60 -> 1.82 | G18: =G7*Inputs!$F$13/60 -> 1.82 | H18: =H7*Inputs!$F$13/60 -> 1.56 | I18: =I7*Inputs!$F$13/60 -> 1.3 | J18: =J7*Inputs!$F$13/60 -> 1.04 | ... N18: =N7*Inputs!$F$13/60 -> 2.08 | O18: =SUM(C18:N18) -> 16.38
B19: Uren: creditvragen | C19: =C8*Inputs!$F$14/60 -> 0.104 | D19: =D8*Inputs!$F$14/60 -> 0.208 | E19: =E8*Inputs!$F$14/60 -> 0.312 | F19: =F8*Inputs!$F$14/60 -> 0.364 | G19: =G8*Inputs!$F$14/60 -> 0.364 | H19: =H8*Inputs!$F$14/60 -> 0.312 | I19: =I8*Inputs!$F$14/60 -> 0.26 | J19: =J8*Inputs!$F$14/60 -> 0.208 | ... N19: =N8*Inputs!$F$14/60 -> 0.416 | O19: =SUM(C19:N19) -> 3.276
B20: Uren: facturatie per partner | C20: =C16*Inputs!$F$18/60 -> 0.33333333 | D20: =D16*Inputs!$F$18/60 -> 0.66666667 | E20: =E16*Inputs!$F$18/60 -> 1 | F20: =F16*Inputs!$F$18/60 -> 1.3333333 | G20: =G16*Inputs!$F$18/60 -> 1.3333333 | H20: =H16*Inputs!$F$18/60 -> 1 | I20: =I16*Inputs!$F$18/60 -> 1 | J20: =J16*Inputs!$F$18/60 -> 0.66666667 | ... N20: =N16*Inputs!$F$18/60 -> 1.3333333 | O20: =SUM(C20:N20) -> 11
B21: Uren: partnerwerving (verloop vervangen) | C21: =C16*Inputs!$F$16*Inputs!$F$15 -> 0.28 | D21: =D16*Inputs!$F$16*Inputs!$F$15 -> 0.56 | E21: =E16*Inputs!$F$16*Inputs!$F$15 -> 0.84 | F21: =F16*Inputs!$F$16*Inputs!$F$15 -> 1.12 | G21: =G16*Inputs!$F$16*Inputs!$F$15 -> 1.12 | H21: =H16*Inputs!$F$16*Inputs!$F$15 -> 0.84 | I21: =I16*Inputs!$F$16*Inputs!$F$15 -> 0.84 | J21: =J16*Inputs!$F$16*Inputs!$F$15 -> 0.56 | ... N21: =N16*Inputs!$F$16*Inputs!$F$15 -> 1.12 | O21: =SUM(C21:N21) -> 9.24
B22: Uren: ads, administratie, platform | C22: =Inputs!$F$19+Inputs!$F$20+Inputs!$F$21 -> 8 | D22: =Inputs!$F$19+Inputs!$F$20+Inputs!$F$21 -> 8 | E22: =Inputs!$F$19+Inputs!$F$20+Inputs!$F$21 -> 8 | F22: =Inputs!$F$19+Inputs!$F$20+Inputs!$F$21 -> 8 | G22: =Inputs!$F$19+Inputs!$F$20+Inputs!$F$21 -> 8 | H22: =Inputs!$F$19+Inputs!$F$20+Inputs!$F$21 -> 8 | I22: =Inputs!$F$19+Inputs!$F$20+Inputs!$F$21 -> 8 | J22: =Inputs!$F$19+Inputs!$F$20+Inputs!$F$21 -> 8 | ... N22: =Inputs!$F$19+Inputs!$F$20+Inputs!$F$21 -> 8 | O22: =SUM(C22:N22) -> 96
B23: Totaal uren eigen tijd per maand | C23: =SUM(C17:C22) -> 10.404 | D23: =SUM(D17:D22) -> 12.808 | E23: =SUM(E17:E22) -> 15.212 | F23: =SUM(F17:F22) -> 16.720667 | G23: =SUM(G17:G22) -> 16.720667 | H23: =SUM(H17:H22) -> 15.212 | I23: =SUM(I17:I22) -> 14.316667 | J23: =SUM(J17:J22) -> 12.808 | ... N23: =SUM(N17:N22) -> 17.616 | O23: =SUM(C23:N23) -> 172.646
B24: Minuten per werkdag | C24: =C23*60/Inputs!$C$29 -> 29.725714 | D24: =D23*60/Inputs!$C$29 -> 36.594286 | E24: =E23*60/Inputs!$C$29 -> 43.462857 | F24: =F23*60/Inputs!$C$29 -> 47.773333 | G24: =G23*60/Inputs!$C$29 -> 47.773333 | H24: =H23*60/Inputs!$C$29 -> 43.462857 | I24: =I23*60/Inputs!$C$29 -> 40.904762 | J24: =J23*60/Inputs!$C$29 -> 36.594286 | ... N24: =N23*60/Inputs!$C$29 -> 50.331429
B25: Eigen tijd à uurtarief | C25: =-C23*Inputs!$C$25 -> -780.3 | D25: =-D23*Inputs!$C$25 -> -960.6 | E25: =-E23*Inputs!$C$25 -> -1140.9 | F25: =-F23*Inputs!$C$25 -> -1254.05 | G25: =-G23*Inputs!$C$25 -> -1254.05 | H25: =-H23*Inputs!$C$25 -> -1140.9 | I25: =-I23*Inputs!$C$25 -> -1073.75 | J25: =-J23*Inputs!$C$25 -> -960.6 | ... N25: =-N23*Inputs!$C$25 -> -1321.2 | O25: =SUM(C25:N25) -> -12948.45
B26: RESULTAAT NA EIGEN TIJD | C26: =C15+C25 -> -577.77398 | D26: =D15+D25 -> -540.54797 | E26: =E15+E25 -> -503.32195 | F26: =F15+F25 -> -507.70894 | G26: =G15+G25 -> -507.70894 | H26: =H15+H25 -> -503.32195 | I26: =I15+I25 -> -544.93496 | J26: =J15+J25 -> -540.54797 | ... N26: =N15+N25 -> -466.09594 | O26: =SUM(C26:N26) -> -6276.3805
B27: Effectief uurloon (cashresultaat / uren) | C27: =IF(C23>0,C15/C23,0) -> 19.466168 | D27: =IF(D23>0,D15/D23,0) -> 32.796067 | E27: =IF(E23>0,E15/E23,0) -> 41.912835 | F27: =IF(F23>0,F15/F23,0) -> 44.635843 | G27: =IF(G23>0,G15/G23,0) -> 44.635843 | H27: =IF(H23>0,H15/H23,0) -> 41.912835 | I27: =IF(I23>0,I15/I23,0) -> 36.937023 | J27: =IF(J23>0,J15/J23,0) -> 32.796067 | ... N27: =IF(N23>0,N15/N23,0) -> 48.54133 | O27: =IF(O23+O31+O33>0,O34/(O23+O31+O33),0) -> 32.579323
B28: Advertentiekost per geldige aanvraag | C28: =IF(C6>0,-C13/C6,0) -> 23.076923 | D28: =IF(D6>0,-D13/D6,0) -> 23.076923 | E28: =IF(E6>0,-E13/E6,0) -> 23.076923 | F28: =IF(F6>0,-F13/F6,0) -> 23.076923 | G28: =IF(G6>0,-G13/G6,0) -> 23.076923 | H28: =IF(H6>0,-H13/H6,0) -> 23.076923 | I28: =IF(I6>0,-I13/I6,0) -> 23.076923 | J28: =IF(J6>0,-J13/J6,0) -> 23.076923 | ... N28: =IF(N6>0,-N13/N6,0) -> 23.076923
B29: Advertentiekost per gefactureerde aanvraag | C29: =IF(C9>0,-C13/C9,0) -> 31.354515 | D29: =IF(D9>0,-D13/D9,0) -> 31.354515 | E29: =IF(E9>0,-E13/E9,0) -> 31.354515 | F29: =IF(F9>0,-F13/F9,0) -> 31.354515 | G29: =IF(G9>0,-G13/G9,0) -> 31.354515 | H29: =IF(H9>0,-H13/H9,0) -> 31.354515 | I29: =IF(I9>0,-I13/I9,0) -> 31.354515 | J29: =IF(J9>0,-J13/J9,0) -> 31.354515 | ... N29: =IF(N9>0,-N13/N9,0) -> 31.354515
B30: Nieuwe partners te werven (groei) | C30: =MAX(0,C16-0) -> 1 | D30: =MAX(0,D16-C16) -> 1 | E30: =MAX(0,E16-D16) -> 1 | F30: =MAX(0,F16-E16) -> 1 | G30: =MAX(0,G16-F16) -> 0 | H30: =MAX(0,H16-G16) -> 0 | I30: =MAX(0,I16-H16) -> 0 | J30: =MAX(0,J16-I16) -> 0 | K30: =MAX(0,K16-J16) -> 0 | ... N30: =MAX(0,N16-M16) -> 1
B31: Uren: werving nieuwe partners | C31: =C30*Inputs!$F$15 -> 4 | D31: =D30*Inputs!$F$15 -> 4 | E31: =E30*Inputs!$F$15 -> 4 | F31: =F30*Inputs!$F$15 -> 4 | G31: =G30*Inputs!$F$15 -> 0 | H31: =H30*Inputs!$F$15 -> 0 | I31: =I30*Inputs!$F$15 -> 0 | J31: =J30*Inputs!$F$15 -> 0 | ... N31: =N30*Inputs!$F$15 -> 4 | O31: =SUM(C31:N31) -> 24
B32: Eenmalige opstart (cash) | C32: =-Inputs!$C$27 -> -70 | D32: 0 | E32: 0 | F32: 0 | G32: 0 | H32: 0 | I32: 0 | J32: 0 | K32: 0 | L32: 0 | M32: 0 | N32: 0 | O32: =SUM(C32:N32) -> -70
B33: Eenmalige tijd (uren) | C33: =Inputs!$C$28 -> 6 | D33: 0 | E33: 0 | F33: 0 | G33: 0 | H33: 0 | I33: 0 | J33: 0 | K33: 0 | L33: 0 | M33: 0 | N33: 0 | O33: =SUM(C33:N33) -> 6
B34: CASHRESULTAAT incl. groei en opstart | C34: =C15+C32 -> 132.52602 | D34: =D15+D32 -> 420.05203 | E34: =E15+E32 -> 637.57805 | F34: =F15+F32 -> 746.34106 | G34: =G15+G32 -> 746.34106 | H34: =H15+H32 -> 637.57805 | I34: =I15+I32 -> 528.81504 | J34: =J15+J32 -> 420.05203 | ... N34: =N15+N32 -> 855.10406 | O34: =SUM(C34:N34) -> 6602.0695
B35: RESULTAAT NA EIGEN TIJD incl. groei en opstart | C35: =C26+C32-(C31+C33)*Inputs!$C$25 -> -1397.774 | D35: =D26+D32-(D31+D33)*Inputs!$C$25 -> -840.54797 | E35: =E26+E32-(E31+E33)*Inputs!$C$25 -> -803.32195 | F35: =F26+F32-(F31+F33)*Inputs!$C$25 -> -807.70894 | G35: =G26+G32-(G31+G33)*Inputs!$C$25 -> -507.70894 | H35: =H26+H32-(H31+H33)*Inputs!$C$25 -> -503.32195 | I35: =I26+I32-(I31+I33)*Inputs!$C$25 -> -544.93496 | J35: =J26+J32-(J31+J33)*Inputs!$C$25 -> -540.54797 | ... N35: =N26+N32-(N31+N33)*Inputs!$C$25 -> -766.09594 | O35: =SUM(C35:N35) -> -8596.3805
B36: Cumulatief resultaat na eigen tijd | C36: =C35 -> -1397.774 | D36: =D35+C36 -> -2238.322 | E36: =E35+D36 -> -3041.6439 | F36: =F35+E36 -> -3849.3528 | G36: =G35+F36 -> -4357.0618 | H36: =H35+G36 -> -4860.3837 | I36: =I35+H36 -> -5405.3187 | J36: =J35+I36 -> -5945.8667 | K36: =K35+J36 -> -6486.4146 | ... N36: =N35+M36 -> -8596.3805
B37: CASH: ontvangen van partners (vorige maand) | C37: 0 | D37: =C10+C11+C12 -> 367.52602 | E37: =D10+D11+D12 -> 735.05203 | F37: =E10+E11+E12 -> 1102.578 | G37: =F10+F11+F12 -> 1286.3411 | H37: =G10+G11+G12 -> 1286.3411 | I37: =H10+H11+H12 -> 1102.578 | J37: =I10+I11+I12 -> 918.81504 | K37: =J10+J11+J12 -> 735.05203 | ... N37: =M10+M11+M12 -> 1102.578 | O37: =SUM(C37:N37) -> 10106.965
B38: CASH: uitgaven (ads, software, opstart) | C38: =C13+C14+C32 -> -235 | D38: =D13+D14+D32 -> -315 | E38: =E13+E14+E32 -> -465 | F38: =F13+F14+F32 -> -540 | G38: =G13+G14+G32 -> -540 | H38: =H13+H14+H32 -> -465 | I38: =I13+I14+I32 -> -390 | J38: =J13+J14+J32 -> -315 | ... N38: =N13+N14+N32 -> -615 | O38: =SUM(C38:N38) -> -4975
B39: CASH: netto maand | C39: =C37+C38 -> -235 | D39: =D37+D38 -> 52.526016 | E39: =E37+E38 -> 270.05203 | F39: =F37+F38 -> 562.57805 | G39: =G37+G38 -> 746.34106 | H39: =H37+H38 -> 821.34106 | I39: =I37+I38 -> 712.57805 | J39: =J37+J38 -> 603.81504 | ... N39: =N37+N38 -> 487.57805 | O39: =SUM(C39:N39) -> 5131.9654
B40: CASH: cumulatief | C40: =C39 -> -235 | D40: =D39+C40 -> -182.47398 | E40: =E39+D40 -> 87.578048 | F40: =F39+E40 -> 650.1561 | G40: =G39+F40 -> 1396.4972 | H40: =H39+G40 -> 2217.8382 | I40: =I39+H40 -> 2930.4163 | J40: =J39+I40 -> 3534.2313 | K40: =K39+J40 -> 3954.2833 | ... N40: =N39+M40 -> 5131.9654
...

Sheet Partnerwaarde
B1: Wat is één aanvaarde aanvraag waard voor een installateur?
B2: Onderbouwing voor de vraagprijs per aanvraag. Alles AANNAME behalve waar een bron staat.
B4: Aanname | C4: Laag | D4: Midden | E4: Hoog | F4: Bron / toelichting
B5: Prijs vervanging gasketel geïnstalleerd (€ excl. btw) | C5: 3000 | D5: 4000 | E5: 6000 | F5: Bron: Trustup prijsgids 2026, condensatieketel geplaatst €3.000–6.000 HTVA (blog.trustup.be). Midden = aanname.
B6: Dekkingsbijdrage installateur (% van prijs, na materiaal en directe arbeid) | C6: 0.2 | D6: 0.25 | E6: 0.3 | F6: AANNAME. Niet publiek gevonden. Vraag in partnergesprek: 'wat houd je over op een gemiddelde vervanging?'.
B7: Kans dat een aanvaarde aanvraag een opdracht wordt | C7: 0.15 | D7: 0.2 | E7: 0.3 | F7: AANNAME. Aanvrager heeft vaak al een offerte → prijsconcurrentie. Meten na pilot: partner rapporteert gewonnen/verloren.
B8: Deel van verwachte marge dat installateur aan klantwerving wil uitgeven | C8: 0.3 | D8: 0.35 | E8: 0.4 | F8: AANNAME. Vraag: 'hoeveel mag een nieuwe vervangingsklant je kosten?'.
B10: Dekkingsbijdrage per gewonnen opdracht (€) | C10: =C5*C6 -> 600 | D10: =D5*D6 -> 1000 | E10: =E5*E6 -> 1800
B11: Verwachte dekkingsbijdrage per aanvaarde aanvraag (€) | C11: =C10*C7 -> 90 | D11: =D10*D7 -> 200 | E11: =E10*E7 -> 540
B12: → Redelijke maximumprijs per aanvaarde aanvraag (€) | C12: =C11*C8 -> 27 | D12: =D11*D8 -> 70 | E12: =E11*E8 -> 216
B13: Partner-ROI bij €80 (verwachte bijdrage / prijs) | C13: =C11/80 -> 1.125 | D13: =D11/80 -> 2.5 | E13: =E11/80 -> 6.75
B15: Benodigde winkans per vraagprijs (bij midden-prijs en midden-marge) | C15: €60 | D15: €80 | E15: €90
B16: Minimale winkans opdat prijs ≤ wervingsbudget | C16: =60/($D$10*$D$8) -> 0.17142857 | D16: =80/($D$10*$D$8) -> 0.22857143 | E16: =90/($D$10*$D$8) -> 0.25714286
B18: Lezing: €60 vraagt ±17% winkans, €80 ±23%, €90 ±26% (midden-aannames). Onder ~15% winkans is €60 al te duur.
B19: Vergelijkingspunt (anekdotisch): Solvari-reviews vermelden ~€20 en ~€45 per GEDEELDE lead (meerdere installateurs). Exclusief + met bestaande offerte rechtvaardigt een hogere prijs enkel als de winkans hoger ligt.
B20: Extra waarde niet meegeteld: onderhoudsklant nadien (gas 2-jaarlijks, ±€100–170 per beurt excl. btw — bronnen Test-Aankoop / Bobex).

Sheet Gevoeligheid
B1: Resultaat NA eigen tijd per maand — vergoeding × CPL
B2: Overige parameters: actief scenario. CPL per inzending.
B3: Inzendingen per maand | C3: 50
B5: CPL ↓ / vergoeding → | C5: 40 | D5: 50 | E5: 60 | F5: 70 | G5: 80 | H5: 90 | I5: 100 | J5: 120
B6: 5 | C6: =$C$3*(Inputs!$F$6*Inputs!$F$7*(1-Inputs!$F$9)*C$5*(1-Inputs!$F$10)*(1-Inputs!$C$26)-'Unit economics'!$C$33-$B6)-'Unit economics'!$C$34 -> -817.01829 | D6: =$C$3*(Inputs!$F$6*Inputs!$F$7*(1-Inputs!$F$9)*D$5*(1-Inputs!$F$10)*(1-Inputs!$C$26)-'Unit economics'!$C$33-$B6)-'Unit economics'!$C$34 -> -587.31453 | E6: =$C$3*(Inputs!$F$6*Inputs!$F$7*(1-Inputs!$F$9)*E$5*(1-Inputs!$F$10)*(1-Inputs!$C$26)-'Unit economics'!$C$33-$B6)-'Unit economics'!$C$34 -> -357.61077 | F6: =$C$3*(Inputs!$F$6*Inputs!$F$7*(1-Inputs!$F$9)*F$5*(1-Inputs!$F$10)*(1-Inputs!$C$26)-'Unit economics'!$C$33-$B6)-'Unit economics'!$C$34 -> -127.90701 | G6: =$C$3*(Inputs!$F$6*Inputs!$F$7*(1-Inputs!$F$9)*G$5*(1-Inputs!$F$10)*(1-Inputs!$C$26)-'Unit economics'!$C$33-$B6)-'Unit economics'!$C$34 -> 101.79675 | H6: =$C$3*(Inputs!$F$6*Inputs!$F$7*(1-Inputs!$F$9)*H$5*(1-Inputs!$F$10)*(1-Inputs!$C$26)-'Unit economics'!$C$33-$B6)-'Unit economics'!$C$34 -> 331.50051 | I6: =$C$3*(Inputs!$F$6*Inputs!$F$7*(1-Inputs!$F$9)*I$5*(1-Inputs!$F$10)*(1-Inputs!$C$26)-'Unit economics'!$C$33-$B6)-'Unit economics'!$C$34 -> 561.20427 | J6: =$C$3*(Inputs!$F$6*Inputs!$F$7*(1-Inputs!$F$9)*J$5*(1-Inputs!$F$10)*(1-Inputs!$C$26)-'Unit economics'!$C$33-$B6)-'Unit economics'!$C$34 -> 1020.6118
B7: 8 | C7: =$C$3*(Inputs!$F$6*Inputs!$F$7*(1-Inputs!$F$9)*C$5*(1-Inputs!$F$10)*(1-Inputs!$C$26)-'Unit economics'!$C$33-$B7)-'Unit economics'!$C$34 -> -967.01829 | D7: =$C$3*(Inputs!$F$6*Inputs!$F$7*(1-Inputs!$F$9)*D$5*(1-Inputs!$F$10)*(1-Inputs!$C$26)-'Unit economics'!$C$33-$B7)-'Unit economics'!$C$34 -> -737.31453 | E7: =$C$3*(Inputs!$F$6*Inputs!$F$7*(1-Inputs!$F$9)*E$5*(1-Inputs!$F$10)*(1-Inputs!$C$26)-'Unit economics'!$C$33-$B7)-'Unit economics'!$C$34 -> -507.61077 | F7: =$C$3*(Inputs!$F$6*Inputs!$F$7*(1-Inputs!$F$9)*F$5*(1-Inputs!$F$10)*(1-Inputs!$C$26)-'Unit economics'!$C$33-$B7)-'Unit economics'!$C$34 -> -277.90701 | G7: =$C$3*(Inputs!$F$6*Inputs!$F$7*(1-Inputs!$F$9)*G$5*(1-Inputs!$F$10)*(1-Inputs!$C$26)-'Unit economics'!$C$33-$B7)-'Unit economics'!$C$34 -> -48.203253 | H7: =$C$3*(Inputs!$F$6*Inputs!$F$7*(1-Inputs!$F$9)*H$5*(1-Inputs!$F$10)*(1-Inputs!$C$26)-'Unit economics'!$C$33-$B7)-'Unit economics'!$C$34 -> 181.50051 | I7: =$C$3*(Inputs!$F$6*Inputs!$F$7*(1-Inputs!$F$9)*I$5*(1-Inputs!$F$10)*(1-Inputs!$C$26)-'Unit economics'!$C$33-$B7)-'Unit economics'!$C$34 -> 411.20427 | J7: =$C$3*(Inputs!$F$6*Inputs!$F$7*(1-Inputs!$F$9)*J$5*(1-Inputs!$F$10)*(1-Inputs!$C$26)-'Unit economics'!$C$33-$B7)-'Unit economics'!$C$34 -> 870.61179
B8: 10 | C8: =$C$3*(Inputs!$F$6*Inputs!$F$7*(1-Inputs!$F$9)*C$5*(1-Inputs!$F$10)*(1-Inputs!$C$26)-'Unit economics'!$C$33-$B8)-'Unit economics'!$C$34 -> -1067.0183 | D8: =$C$3*(Inputs!$F$6*Inputs!$F$7*(1-Inputs!$F$9)*D$5*(1-Inputs!$F$10)*(1-Inputs!$C$26)-'Unit economics'!$C$33-$B8)-'Unit economics'!$C$34 -> -837.31453 | E8: =$C$3*(Inputs!$F$6*Inputs!$F$7*(1-Inputs!$F$9)*E$5*(1-Inputs!$F$10)*(1-Inputs!$C$26)-'Unit economics'!$C$33-$B8)-'Unit economics'!$C$34 -> -607.61077 | F8: =$C$3*(Inputs!$F$6*Inputs!$F$7*(1-Inputs!$F$9)*F$5*(1-Inputs!$F$10)*(1-Inputs!$C$26)-'Unit economics'!$C$33-$B8)-'Unit economics'!$C$34 -> -377.90701 | G8: =$C$3*(Inputs!$F$6*Inputs!$F$7*(1-Inputs!$F$9)*G$5*(1-Inputs!$F$10)*(1-Inputs!$C$26)-'Unit economics'!$C$33-$B8)-'Unit economics'!$C$34 -> -148.20325 | H8: =$C$3*(Inputs!$F$6*Inputs!$F$7*(1-Inputs!$F$9)*H$5*(1-Inputs!$F$10)*(1-Inputs!$C$26)-'Unit economics'!$C$33-$B8)-'Unit economics'!$C$34 -> 81.500507 | I8: =$C$3*(Inputs!$F$6*Inputs!$F$7*(1-Inputs!$F$9)*I$5*(1-Inputs!$F$10)*(1-Inputs!$C$26)-'Unit economics'!$C$33-$B8)-'Unit economics'!$C$34 -> 311.20427 | J8: =$C$3*(Inputs!$F$6*Inputs!$F$7*(1-Inputs!$F$9)*J$5*(1-Inputs!$F$10)*(1-Inputs!$C$26)-'Unit economics'!$C$33-$B8)-'Unit economics'!$C$34 -> 770.61179
B9: 12 | C9: =$C$3*(Inputs!$F$6*Inputs!$F$7*(1-Inputs!$F$9)*C$5*(1-Inputs!$F$10)*(1-Inputs!$C$26)-'Unit economics'!$C$33-$B9)-'Unit economics'!$C$34 -> -1167.0183 | D9: =$C$3*(Inputs!$F$6*Inputs!$F$7*(1-Inputs!$F$9)*D$5*(1-Inputs!$F$10)*(1-Inputs!$C$26)-'Unit economics'!$C$33-$B9)-'Unit economics'!$C$34 -> -937.31453 | E9: =$C$3*(Inputs!$F$6*Inputs!$F$7*(1-Inputs!$F$9)*E$5*(1-Inputs!$F$10)*(1-Inputs!$C$26)-'Unit economics'!$C$33-$B9)-'Unit economics'!$C$34 -> -707.61077 | F9: =$C$3*(Inputs!$F$6*Inputs!$F$7*(1-Inputs!$F$9)*F$5*(1-Inputs!$F$10)*(1-Inputs!$C$26)-'Unit economics'!$C$33-$B9)-'Unit economics'!$C$34 -> -477.90701 | G9: =$C$3*(Inputs!$F$6*Inputs!$F$7*(1-Inputs!$F$9)*G$5*(1-Inputs!$F$10)*(1-Inputs!$C$26)-'Unit economics'!$C$33-$B9)-'Unit economics'!$C$34 -> -248.20325 | H9: =$C$3*(Inputs!$F$6*Inputs!$F$7*(1-Inputs!$F$9)*H$5*(1-Inputs!$F$10)*(1-Inputs!$C$26)-'Unit economics'!$C$33-$B9)-'Unit economics'!$C$34 -> -18.499493 | I9: =$C$3*(Inputs!$F$6*Inputs!$F$7*(1-Inputs!$F$9)*I$5*(1-Inputs!$F$10)*(1-Inputs!$C$26)-'Unit economics'!$C$33-$B9)-'Unit economics'!$C$34 -> 211.20427 | J9: =$C$3*(Inputs!$F$6*Inputs!$F$7*(1-Inputs!$F$9)*J$5*(1-Inputs!$F$10)*(1-Inputs!$C$26)-'Unit economics'!$C$33-$B9)-'Unit economics'!$C$34 -> 670.61179
B10: 15 | C10: =$C$3*(Inputs!$F$6*Inputs!$F$7*(1-Inputs!$F$9)*C$5*(1-Inputs!$F$10)*(1-Inputs!$C$26)-'Unit economics'!$C$33-$B10)-'Unit economics'!$C$34 -> -1317.0183 | D10: =$C$3*(Inputs!$F$6*Inputs!$F$7*(1-Inputs!$F$9)*D$5*(1-Inputs!$F$10)*(1-Inputs!$C$26)-'Unit economics'!$C$33-$B10)-'Unit economics'!$C$34 -> -1087.3145 | E10: =$C$3*(Inputs!$F$6*Inputs!$F$7*(1-Inputs!$F$9)*E$5*(1-Inputs!$F$10)*(1-Inputs!$C$26)-'Unit economics'!$C$33-$B10)-'Unit economics'!$C$34 -> -857.61077 | F10: =$C$3*(Inputs!$F$6*Inputs!$F$7*(1-Inputs!$F$9)*F$5*(1-Inputs!$F$10)*(1-Inputs!$C$26)-'Unit economics'!$C$33-$B10)-'Unit economics'!$C$34 -> -627.90701 | G10: =$C$3*(Inputs!$F$6*Inputs!$F$7*(1-Inputs!$F$9)*G$5*(1-Inputs!$F$10)*(1-Inputs!$C$26)-'Unit economics'!$C$33-$B10)-'Unit economics'!$C$34 -> -398.20325 | H10: =$C$3*(Inputs!$F$6*Inputs!$F$7*(1-Inputs!$F$9)*H$5*(1-Inputs!$F$10)*(1-Inputs!$C$26)-'Unit economics'!$C$33-$B10)-'Unit economics'!$C$34 -> -168.49949 | I10: =$C$3*(Inputs!$F$6*Inputs!$F$7*(1-Inputs!$F$9)*I$5*(1-Inputs!$F$10)*(1-Inputs!$C$26)-'Unit economics'!$C$33-$B10)-'Unit economics'!$C$34 -> 61.204267 | J10: =$C$3*(Inputs!$F$6*Inputs!$F$7*(1-Inputs!$F$9)*J$5*(1-Inputs!$F$10)*(1-Inputs!$C$26)-'Unit economics'!$C$33-$B10)-'Unit economics'!$C$34 -> 520.61179
B11: 18 | C11: =$C$3*(Inputs!$F$6*Inputs!$F$7*(1-Inputs!$F$9)*C$5*(1-Inputs!$F$10)*(1-Inputs!$C$26)-'Unit economics'!$C$33-$B11)-'Unit economics'!$C$34 -> -1467.0183 | D11: =$C$3*(Inputs!$F$6*Inputs!$F$7*(1-Inputs!$F$9)*D$5*(1-Inputs!$F$10)*(1-Inputs!$C$26)-'Unit economics'!$C$33-$B11)-'Unit economics'!$C$34 -> -1237.3145 | E11: =$C$3*(Inputs!$F$6*Inputs!$F$7*(1-Inputs!$F$9)*E$5*(1-Inputs!$F$10)*(1-Inputs!$C$26)-'Unit economics'!$C$33-$B11)-'Unit economics'!$C$34 -> -1007.6108 | F11: =$C$3*(Inputs!$F$6*Inputs!$F$7*(1-Inputs!$F$9)*F$5*(1-Inputs!$F$10)*(1-Inputs!$C$26)-'Unit economics'!$C$33-$B11)-'Unit economics'!$C$34 -> -777.90701 | G11: =$C$3*(Inputs!$F$6*Inputs!$F$7*(1-Inputs!$F$9)*G$5*(1-Inputs!$F$10)*(1-Inputs!$C$26)-'Unit economics'!$C$33-$B11)-'Unit economics'!$C$34 -> -548.20325 | H11: =$C$3*(Inputs!$F$6*Inputs!$F$7*(1-Inputs!$F$9)*H$5*(1-Inputs!$F$10)*(1-Inputs!$C$26)-'Unit economics'!$C$33-$B11)-'Unit economics'!$C$34 -> -318.49949 | I11: =$C$3*(Inputs!$F$6*Inputs!$F$7*(1-Inputs!$F$9)*I$5*(1-Inputs!$F$10)*(1-Inputs!$C$26)-'Unit economics'!$C$33-$B11)-'Unit economics'!$C$34 -> -88.795733 | J11: =$C$3*(Inputs!$F$6*Inputs!$F$7*(1-Inputs!$F$9)*J$5*(1-Inputs!$F$10)*(1-Inputs!$C$26)-'Unit economics'!$C$33-$B11)-'Unit economics'!$C$34 -> 370.61179
B12: 22 | C12: =$C$3*(Inputs!$F$6*Inputs!$F$7*(1-Inputs!$F$9)*C$5*(1-Inputs!$F$10)*(1-Inputs!$C$26)-'Unit economics'!$C$33-$B12)-'Unit economics'!$C$34 -> -1667.0183 | D12: =$C$3*(Inputs!$F$6*Inputs!$F$7*(1-Inputs!$F$9)*D$5*(1-Inputs!$F$10)*(1-Inputs!$C$26)-'Unit economics'!$C$33-$B12)-'Unit economics'!$C$34 -> -1437.3145 | E12: =$C$3*(Inputs!$F$6*Inputs!$F$7*(1-Inputs!$F$9)*E$5*(1-Inputs!$F$10)*(1-Inputs!$C$26)-'Unit economics'!$C$33-$B12)-'Unit economics'!$C$34 -> -1207.6108 | F12: =$C$3*(Inputs!$F$6*Inputs!$F$7*(1-Inputs!$F$9)*F$5*(1-Inputs!$F$10)*(1-Inputs!$C$26)-'Unit economics'!$C$33-$B12)-'Unit economics'!$C$34 -> -977.90701 | G12: =$C$3*(Inputs!$F$6*Inputs!$F$7*(1-Inputs!$F$9)*G$5*(1-Inputs!$F$10)*(1-Inputs!$C$26)-'Unit economics'!$C$33-$B12)-'Unit economics'!$C$34 -> -748.20325 | H12: =$C$3*(Inputs!$F$6*Inputs!$F$7*(1-Inputs!$F$9)*H$5*(1-Inputs!$F$10)*(1-Inputs!$C$26)-'Unit economics'!$C$33-$B12)-'Unit economics'!$C$34 -> -518.49949 | I12: =$C$3*(Inputs!$F$6*Inputs!$F$7*(1-Inputs!$F$9)*I$5*(1-Inputs!$F$10)*(1-Inputs!$C$26)-'Unit economics'!$C$33-$B12)-'Unit economics'!$C$34 -> -288.79573 | J12: =$C$3*(Inputs!$F$6*Inputs!$F$7*(1-Inputs!$F$9)*J$5*(1-Inputs!$F$10)*(1-Inputs!$C$26)-'Unit economics'!$C$33-$B12)-'Unit economics'!$C$34 -> 170.61179
B13: 30 | C13: =$C$3*(Inputs!$F$6*Inputs!$F$7*(1-Inputs!$F$9)*C$5*(1-Inputs!$F$10)*(1-Inputs!$C$26)-'Unit economics'!$C$33-$B13)-'Unit economics'!$C$34 -> -2067.0183 | D13: =$C$3*(Inputs!$F$6*Inputs!$F$7*(1-Inputs!$F$9)*D$5*(1-Inputs!$F$10)*(1-Inputs!$C$26)-'Unit economics'!$C$33-$B13)-'Unit economics'!$C$34 -> -1837.3145 | E13: =$C$3*(Inputs!$F$6*Inputs!$F$7*(1-Inputs!$F$9)*E$5*(1-Inputs!$F$10)*(1-Inputs!$C$26)-'Unit economics'!$C$33-$B13)-'Unit economics'!$C$34 -> -1607.6108 | F13: =$C$3*(Inputs!$F$6*Inputs!$F$7*(1-Inputs!$F$9)*F$5*(1-Inputs!$F$10)*(1-Inputs!$C$26)-'Unit economics'!$C$33-$B13)-'Unit economics'!$C$34 -> -1377.907 | G13: =$C$3*(Inputs!$F$6*Inputs!$F$7*(1-Inputs!$F$9)*G$5*(1-Inputs!$F$10)*(1-Inputs!$C$26)-'Unit economics'!$C$33-$B13)-'Unit economics'!$C$34 -> -1148.2033 | H13: =$C$3*(Inputs!$F$6*Inputs!$F$7*(1-Inputs!$F$9)*H$5*(1-Inputs!$F$10)*(1-Inputs!$C$26)-'Unit economics'!$C$33-$B13)-'Unit economics'!$C$34 -> -918.49949 | I13: =$C$3*(Inputs!$F$6*Inputs!$F$7*(1-Inputs!$F$9)*I$5*(1-Inputs!$F$10)*(1-Inputs!$C$26)-'Unit economics'!$C$33-$B13)-'Unit economics'!$C$34 -> -688.79573 | J13: =$C$3*(Inputs!$F$6*Inputs!$F$7*(1-Inputs!$F$9)*J$5*(1-Inputs!$F$10)*(1-Inputs!$C$26)-'Unit economics'!$C$33-$B13)-'Unit economics'!$C$34 -> -229.38821
B14: 40 | C14: =$C$3*(Inputs!$F$6*Inputs!$F$7*(1-Inputs!$F$9)*C$5*(1-Inputs!$F$10)*(1-Inputs!$C$26)-'Unit economics'!$C$33-$B14)-'Unit economics'!$C$34 -> -2567.0183 | D14: =$C$3*(Inputs!$F$6*Inputs!$F$7*(1-Inputs!$F$9)*D$5*(1-Inputs!$F$10)*(1-Inputs!$C$26)-'Unit economics'!$C$33-$B14)-'Unit economics'!$C$34 -> -2337.3145 | E14: =$C$3*(Inputs!$F$6*Inputs!$F$7*(1-Inputs!$F$9)*E$5*(1-Inputs!$F$10)*(1-Inputs!$C$26)-'Unit economics'!$C$33-$B14)-'Unit economics'!$C$34 -> -2107.6108 | F14: =$C$3*(Inputs!$F$6*Inputs!$F$7*(1-Inputs!$F$9)*F$5*(1-Inputs!$F$10)*(1-Inputs!$C$26)-'Unit economics'!$C$33-$B14)-'Unit economics'!$C$34 -> -1877.907 | G14: =$C$3*(Inputs!$F$6*Inputs!$F$7*(1-Inputs!$F$9)*G$5*(1-Inputs!$F$10)*(1-Inputs!$C$26)-'Unit economics'!$C$33-$B14)-'Unit economics'!$C$34 -> -1648.2033 | H14: =$C$3*(Inputs!$F$6*Inputs!$F$7*(1-Inputs!$F$9)*H$5*(1-Inputs!$F$10)*(1-Inputs!$C$26)-'Unit economics'!$C$33-$B14)-'Unit economics'!$C$34 -> -1418.4995 | I14: =$C$3*(Inputs!$F$6*Inputs!$F$7*(1-Inputs!$F$9)*I$5*(1-Inputs!$F$10)*(1-Inputs!$C$26)-'Unit economics'!$C$33-$B14)-'Unit economics'!$C$34 -> -1188.7957 | J14: =$C$3*(Inputs!$F$6*Inputs!$F$7*(1-Inputs!$F$9)*J$5*(1-Inputs!$F$10)*(1-Inputs!$C$26)-'Unit economics'!$C$33-$B14)-'Unit economics'!$C$34 -> -729.38821
B16: Groen = winst na €75/u eigen tijd. Zoek de cel met je gemeten CPL en de prijs uit je getekende pilots.

Sheet Beslisdrempels
B1: Doorgaan / bijsturen / stoppen
B2: Beoordelen na de pilot: minstens 20 geldige aanvragen of 45 dagen, wat eerst komt. Kleine aantallen: lees als richting, niet als vast cijfer.
B4: Meetpunt | C4: DOORGAAN | D4: BIJSTUREN | E4: STOPPEN | F4: Gemeten | G4: Oordeel
B5: Getekende pilots (≥ €60, startregio gedekt) | C5: ≥ 3 en ≥ 2 aan ≥ €80 | D5: 3 maar enkel aan €60–79 | E5: < 3 na 40 belpogingen | G5: =IF(F5="","",IF(F5>=3,"doorgaan",IF(F5>=2,"bijsturen","stoppen")))
B6: Vergoeding per aanvaarde aanvraag (gewogen gem.) | C6: ≥ €80 | D6: €60–79 | E6: < €60 | G6: =IF(F6="","",IF(F6>=80,"doorgaan",IF(F6>=60,"bijsturen","stoppen")))
B7: CPL per formulierinzending | C7: ≤ €15 | D7: €15–25 | E7: > €25 na ≥ €600 ads | G7: =IF(F7="","",IF(F7<=15,"doorgaan",IF(F7<=25,"bijsturen","stoppen")))
B8: Geldige inzendingen | C8: ≥ 65% | D8: 50–65% | E8: < 50% | G8: =IF(F8="","",IF(F8>=0.65,"doorgaan",IF(F8>=0.5,"bijsturen","stoppen")))
B9: Aanvaard door 1e of 2e partner | C9: ≥ 75% | D9: 50–75% | E9: < 50% | G9: =IF(F9="","",IF(F9>=0.75,"doorgaan",IF(F9>=0.5,"bijsturen","stoppen")))
B10: Goedgekeurde credits | C10: ≤ 10% | D10: 10–20% | E10: > 20% | G10: =IF(F10="","",IF(F10<=0.1,"doorgaan",IF(F10<=0.2,"bijsturen","stoppen")))
B11: Herhaalaankoop: partner koopt na pilot verder | C11: ≥ 2 partners | D11: 1 partner | E11: 0 partners | G11: =IF(F11="","",IF(F11>=2,"doorgaan",IF(F11>=1,"bijsturen","stoppen")))
B12: Modelresultaat na eigen tijd bij 50 inzendingen/m (met gemeten waarden) | C12: > €0 | D12: −€500 tot €0 | E12: < −€500 | F12: ='Unit economics'!D26 -> -428.86992 | G12: =IF(F12="","",IF(F12>=0,"doorgaan",IF(F12>=-500,"bijsturen","stoppen"))) -> bijsturen
B14: Regel: één 'stoppen' op pilots, vergoeding of CPL = stoppen of fundamenteel herzien. Overige 'stoppen' = eerst bijsturen, opnieuw meten na 20 aanvragen.
B15: Modelregel: vul gemeten waarden in tab Inputs (kolom 'Echt gemeten') en lees Unit economics kolom D (50 inzendingen).

Sheet Testbudget
B1: Validatietest — externe uitgaven (niets uitgeven zonder akkoord Mohamed)
B3: Post | C3: Bedrag | D3: Voorwaarde
B4: Google Ads NL (Vlaamse Rand) | C4: 350 | D4: Enkel na ≥ 3 getekende pilots en akkoord
B5: Google Ads FR (Brussel) | C5: 400 | D5: Idem; Brussel is grotendeels Franstalig
B6: Reserve winnende taal | C6: 150 | D6: Enkel als CPL ≤ €25 na eerste €400
B7: Domein + mailbox | C7: 70 | D7: Bv. domein ±€10–15/jaar + professionele mailbox; te bevestigen
B8: Buffer | C8: 30
B9: Totaal | C9: =SUM(C4:C8) -> 1000
B10: Binnen testplafond? | C10: =IF(C9<=Inputs!$C$32,"ja","NEE") -> ja
